I'm sorry, but an uncaught exception occurred.

While running game code:
  File "game/script.rpy", line 27, in script
    e "You've created a new Ren'Py game."
Exception: Sayer 'e' is not defined.

-- Full Traceback ------------------------------------------------------------

Full traceback:
  File "game/script.rpy", line 27, in script
    e "You've created a new Ren'Py game."
  File "C:\Users\webbl\OneDrive\Desktop\renpy-8.3.4-sdk\renpy\ast.py", line 2579, in execute
    Say.execute(self)
  File "C:\Users\webbl\OneDrive\Desktop\renpy-8.3.4-sdk\renpy\ast.py", line 581, in execute
    who = eval_who(self.who, self.who_fast)
  File "C:\Users\webbl\OneDrive\Desktop\renpy-8.3.4-sdk\renpy\ast.py", line 470, in eval_who
    raise Exception("Sayer '%s' is not defined." % who)
Exception: Sayer 'e' is not defined.

Windows-10-10.0.26100 AMD64
Ren'Py 8.3.4.24120703
December Paased Without a Sound 1.0
Thu Feb  6 11:42:41 2025
